Workbook
Name _DEP1: '[1]Internal Data'!$P$4:$P$36
Name _ECHO: '[2]Internal Data'!$A$4:$A$6
Name _PRO1: '[1]Internal Data'!$D$4:$D$23
Name _REV1: '[1]Internal Data'!$D$29:$D$47
Name CHECK: '[3]Internal Data'!$B$4:$B$6
Name CPRO1: '[1]Internal Data'!$N$4:$N$16
Name CPROV: Données!$R$25:$R$38
Name CPTES: Données!$J$7:$J$9
Name CREDIT: Données!$L$25:$L$47
Name DATE: Données!$N$25:$N$56
Name DEBUDGET: Données!$H$8:$H$23
Name DEBUDGET1: Données!$H$8:$H$15
Name DEPFIXE: '[4]Données internes'!$Q$4:$Q$44
Name DEPVAR: '[4]Données internes'!$S$4:$S$14
Name DFIX: Données!$T$25:$T$56
Name DIME: Données!$F$33:$F$34
Name DVAR: Données!$V$25:$V$34
Name ECHO: '[1]Internal Data'!$A$4:$A$6
Name EPAR: Données!$H$25:$H$51
Name EPAR0: '[1]Internal Data'!$H$3:$H$25
Name EPAR1: '[1]Internal Data'!$F$3:$F$30
Name EPARBUT: Données!$J$25:$J$43
Name EPAROBJ: '[3]Internal Data'!$H$4:$H$23
Name MOISP: '[5]Internal Data'!$L$4:$L$35
Name MOISP1: '[1]Internal Data'!$L$3:$L$35
Name NBMAJ: Données!$F$7:$F$14
Name NBMAJ1: Données!$F$8:$F$14
Name NBMIN: Données!$D$7:$D$14
Name NBMIN1: Données!$D$8:$D$14
Name OBJEPAR: '[4]Données internes'!$E$4:$E$28
Name OK: Données!$F$25:$F$27
Name PASS1: '[1]Internal Data'!$J$4:$J$27
Name PASSIFS: '[4]Données internes'!$I$4:$I$31
Name PRELEV: '[4]Données internes'!$K$4:$K$36
Name PROV: Données!$P$25:$P$45
Name PROVCOM: '[4]Données internes'!$M$4:$M$17
Name REV: Données!$D$25:$D$45
Name REVENUS: '[4]Données internes'!$C$4:$C$28
Name SITFA: Données!$B$7:$B$11
Name SITFA1: Données!$B$8:$B$11
Name TYPEPAR: '[4]Données internes'!$G$4:$G$36
Name VCDE: Données!$B$64:$B$94

Sheet Menu
B5: Cliquer pour accéder à votre Budget Gold
I6: Version 2026 Révision VMAX EUR
J7: par Christian Saboukoulou
B9: L'expérience de la planification budgétaire au service de vos finances et de vos projets
B12: MENU DE CONFIGURATION GENERALE
B14: Etape 1 | C14: Nom | F14: PIZEUIL | G14: <- | H14: à remplir | J14: Gestion immobilière ImmoView 1
B16: Etape 2 | C16: Situation familiale | F16: célibataire | G16: <- | H16: sélectionner
B18: Etape 3 | C18: Nombre d'enfants mineurs | F18: 0 | G18: <- | H18: sélectionner | J18: Gestion immobilière ImmoView 2
B20: Etape 4 | C20: Nombre d'enfants majeurs | F20: 0 | G20: <- | H20: sélectionner
B22: Etape 5 | C22: Mois de démarrage du budget | F22: 46174 | G22: <- | H22: sélectionner | J22: Gestion immobilière ImmoView 3
B24: Etape 6 | C24: Configurer vos comptes bancaires et vos solutions d'épargne en cliquant ici
B26: Etape 7 | C26: Accéder à votre tableau Budget Gold | J26: Budget d'un mariage Mariage-Gold
C32: Informations et avertissements :
C33: Cet ouvrage est la propriété unique de l’auteur. Il est protégé par le Code de la propriété intellectuelle (CPI) qui stipule que « l’auteur
C34: d’une œuvre de l’esprit jouit sur cette œuvre, du seul fait de sa création, d’un droit de propriété incorporelle exclusif et opposable à tous.
C35: Ce droit comporte des attributs d’ordre intellectuel et moral ainsi que des attributs d’ordre patrimonial ». L’ensemble de ces droits figure
C36: dans la première partie du code de la propriété intellectuelle qui codifie les lois du 11 mars 1957 et du 3 juillet 1985.
C37: Tous droits réservés pour tous pays. En application des lois rappelées ci-dessus, aucun extrait de ce livret ne peut être reproduit, par
C38: quelque procédé que ce soit, sans l’autorisation écrite de l’auteur.
C40: Limitations et risques :
C41: Budget Gold est un outil d'aide à la planification budgétaire. Son usage adéquat peut permettre l'amélioration de la gestion budgétaire de
C42: celui qui l'utilise. Toutefois, cela n'est pas une garantie absolue, car plusieurs paramètres externes peuvent le rendre inefficace.
C43: Par ailleurs, une vérification des formules a été faite, néanmoins, il est toujours possible qu'une erreur se soit glissée, faussant ainsi certains
C44: résultats de formules. Le concepteur du fichier Budget Gold ne peut être tenu pour responsable des éventuels problèmes financiers
... C46: Toute utilisation de Budget Gold par l'utilisateur entraine l'acceptation de ces limitations et risques.
H47: © Copyright 2003-2026, Christian SABOUKOULOU, Tous droits réservés

Sheet Menu 2
B2: Retour au Budget | E2: Retour au Menu
B6: Listez tous vos comptes courants :
B7: Les comptes courants que vous possédez.
C8: 1 | E8: Compte courant - BANXO | G8: Exemples : | H8: Compte courant - Romuald (BNP Paribas)
C9: 2 | E9: Compte courant - Revolut | H9: Compte courant - Romuald (CIC)
C10: 3 | H10: Compte courant - Esther (Banque Postale)
C11: =C10+1 -> 4 | H11: Enveloppe
C12: =C11+1 -> 5 | H12: Caisse
C13: =C12+1 -> 6
C14: =C13+1 -> 7
C15: =C14+1 -> 8
C16: =C15+1 -> 9
C17: =C16+1 -> 10
C18: =C17+1 -> 11
C19: =C18+1 -> 12
B22: Listez toutes vos formules d'épargne :
B23: Comptes d'épargne, assurances-vie
B24: Comptes d'investissements, tirelires, etc. | C24: 1 | E24: Livret A - BANXO | G24: Exemples : | H24: Livret d'épargne - Romuald
C25: 2 | E25: PEA - Bourse direct | H25: Livret A - Bébé Bambino
C26: 3 | E26: Assurance vie - Finarylife | H26: Livret Jeune - Romuald
C27: =C26+1 -> 4 | E27: Placements financiers | H27: PEA BNP Paribas - Esther
C28: =C27+1 -> 5 | E28: Fonds euros - Finarylife | H28: Tirelire
C29: =C28+1 -> 6 | H29: Enveloppe
C30: =C29+1 -> 7
C31: =C30+1 -> 8
C32: =C31+1 -> 9
C33: =C32+1 -> 10
C34: =C33+1 -> 11
C35: =C34+1 -> 12
C36: =C35+1 -> 13
C37: =C36+1 -> 14
C38: =C37+1 -> 15
C39: =C38+1 -> 16
C40: =C39+1 -> 17
C41: =C40+1 -> 18
... C52: =C51+1 -> 29
C53: =C52+1 -> 30 | E53: PATRIMOINE

Sheet Budget Gold
A2: Accès au MENU | F2: Si la vie commençait par la fin, on prendrait davantage le temps de bien préparer les choses importantes
AT3: EXTRA-PROJECTION
A4: Simulateur d'épargne | F4: =CONCATENATE("Budget de ",IF(Menu!F14="","",Menu!F14)) -> Budget de PIZEUIL | I4: =IF(BB28>0,CONCATENATE("Total des revenus annuels : ",INT(BB28),"€ (",INT(BB29),"€/mois)"),"") -> Total des revenus annuels : 42000€ (3500€/mois) | S4: =Menu!I6 -> Version 2026 Révision VMAX EUR | AA4: =I4 -> Total des revenus annuels : 42000€ (3500€/mois) | AY4: BILAN ANNUEL
I5: =IF(I4="","",CONCATENATE("Balance annuelle générale : ",INT(BB267),"€ (",INT(BB267/12),"€/mois)")) -> Balance annuelle générale : 21642€ (1803€/mois) | AA5: =I5 -> Balance annuelle générale : 21642€ (1803€/mois) | AT5: Horizon 2 ans | AU5: Horizon 5 ans
I7: =(Menu!F22) -> 46174 | L7: =32+I7 -> 46206 | O7: =32+L7 -> 46238 | R7: =32+O7 -> 46270 | U7: =32+R7 -> 46302 | X7: =32+U7 -> 46334 | AA7: =32+X7 -> 46366 | AD7: =32+AA7 -> 46398 | AG7: =32+AD7 -> 46430 | AJ7: =32+AG7 -> 46462 | AM7: =32+AJ7 -> 46494 | AP7: =32+AM7 -> 46526 | AY7: REVENUS
E8: REVENUS
E9: Dîme | F9: Configurez vos comptes courants (en cliquant ici) | BB9: Cumul annuel | BC9: % | BD9: Moy. mensuelle | BE9: Rang
D10: 1 | E10: oui | F10: SALAIRE | G10: Compte courant - BANXO | I10: 3500 | K10: ea | L10: 3500 | N10: ea | O10: 3500 | Q10: ea | R10: 3500 | T10: ea | U10: 3500 | W10: ea | X10: 3500 | Z10: ea | AA10: 3500 | AC10: ea | AD10: 3500 | AF10: ea | AG10: 3500 | AI10: ea | AJ10: 3500 | AL10: ea | AM10: 3500 | AO10: ea | AP10: 3500 | AR10: ea | AY10: =F10 -> SALAIRE | BB10: =SUM(I10:AR10) -> 42000 | BC10: =IF(BB28=0,0,BB10/BB28) -> 1 | BD10: =BB10/12 -> 3500 | BE10: =IF(BD10=0,"",RANK(BD10,BD$10:BD$27,0)) -> 1 | BF10: =IF(BD10=0,"",IF(BE10=1,"er","ème")) -> er
D11: =1+D10 -> 2 | E11: non | F11: Revenu à configurer | G11: - sélectionner - | AY11: =F11 -> Revenu à configurer | BB11: =SUM(I11:AR11) -> 0 | BC11: =IF(BB28=0,0,BB11/BB28) -> 0 | BD11: =BB11/12 -> 0 | BE11: =IF(BD11=0,"",RANK(BD11,BD$10:BD$27,0)) | BF11: =IF(BD11=0,"",IF(BE11=1,"er","ème"))
D12: =1+D11 -> 3 | E12: non | F12: Revenu à configurer | G12: - sélectionner - | AY12: =F12 -> Revenu à configurer | BB12: =SUM(I12:AR12) -> 0 | BC12: =IF(BB28=0,0,BB12/BB28) -> 0 | BD12: =BB12/12 -> 0 | BE12: =IF(BD12=0,"",RANK(BD12,BD$10:BD$27,0)) | BF12: =IF(BD12=0,"",IF(BE12=1,"er","ème"))
D13: =1+D12 -> 4 | E13: non | F13: Revenu à configurer | G13: - sélectionner - | AY13: =F13 -> Revenu à configurer | BB13: =SUM(I13:AR13) -> 0 | BC13: =IF(BB28=0,0,BB13/BB28) -> 0 | BD13: =BB13/12 -> 0 | BE13: =IF(BD13=0,"",RANK(BD13,BD$10:BD$27,0)) | BF13: =IF(BD13=0,"",IF(BE13=1,"er","ème"))
D14: =1+D13 -> 5 | E14: non | F14: Revenu à configurer | G14: - sélectionner - | AY14: =F14 -> Revenu à configurer | BB14: =SUM(I14:AR14) -> 0 | BC14: =IF(BB28=0,0,BB14/BB28) -> 0 | BD14: =BB14/12 -> 0 | BE14: =IF(BD14=0,"",RANK(BD14,BD$10:BD$27,0)) | BF14: =IF(BD14=0,"",IF(BE14=1,"er","ème"))
D15: =1+D14 -> 6 | E15: non | F15: Revenu à configurer | G15: - sélectionner - | AY15: =F15 -> Revenu à configurer | BB15: =SUM(I15:AR15) -> 0 | BC15: =IF(BB28=0,0,BB15/BB28) -> 0 | BD15: =BB15/12 -> 0 | BE15: =IF(BD15=0,"",RANK(BD15,BD$10:BD$27,0)) | BF15: =IF(BD15=0,"",IF(BE15=1,"er","ème"))
D16: =1+D15 -> 7 | E16: non | F16: Revenu à configurer | G16: - sélectionner - | AY16: =F16 -> Revenu à configurer | BB16: =SUM(I16:AR16) -> 0 | BC16: =IF(BB28=0,0,BB16/BB28) -> 0 | BD16: =BB16/12 -> 0 | BE16: =IF(BD16=0,"",RANK(BD16,BD$10:BD$27,0)) | BF16: =IF(BD16=0,"",IF(BE16=1,"er","ème"))
D17: =1+D16 -> 8 | E17: non | F17: Revenu à configurer | G17: - sélectionner - | AY17: =F17 -> Revenu à configurer | BB17: =SUM(I17:AR17) -> 0 | BC17: =IF(BB28=0,0,BB17/BB28) -> 0 | BD17: =BB17/12 -> 0 | BE17: =IF(BD17=0,"",RANK(BD17,BD$10:BD$27,0)) | BF17: =IF(BD17=0,"",IF(BE17=1,"er","ème"))
D18: =1+D17 -> 9 | E18: non | F18: Revenu à configurer | G18: - sélectionner - | AY18: =F18 -> Revenu à configurer | BB18: =SUM(I18:AR18) -> 0 | BC18: =IF(BB28=0,0,BB18/BB28) -> 0 | BD18: =BB18/12 -> 0 | BE18: =IF(BD18=0,"",RANK(BD18,BD$10:BD$27,0)) | BF18: =IF(BD18=0,"",IF(BE18=1,"er","ème"))
D19: =1+D18 -> 10 | E19: non | F19: Revenu à configurer | G19: - sélectionner - | AY19: =F19 -> Revenu à configurer | BB19: =SUM(I19:AR19) -> 0 | BC19: =IF(BB28=0,0,BB19/BB28) -> 0 | BD19: =BB19/12 -> 0 | BE19: =IF(BD19=0,"",RANK(BD19,BD$10:BD$27,0)) | BF19: =IF(BD19=0,"",IF(BE19=1,"er","ème"))
D20: =1+D19 -> 11 | E20: non | F20: Revenu à configurer | G20: - sélectionner - | AY20: =F20 -> Revenu à configurer | BB20: =SUM(I20:AR20) -> 0 | BC20: =IF(BB28=0,0,BB20/BB28) -> 0 | BD20: =BB20/12 -> 0 | BE20: =IF(BD20=0,"",RANK(BD20,BD$10:BD$27,0)) | BF20: =IF(BD20=0,"",IF(BE20=1,"er","ème"))
D21: =1+D20 -> 12 | E21: non | F21: Revenu à configurer | G21: - sélectionner - | AY21: =F21 -> Revenu à configurer | BB21: =SUM(I21:AR21) -> 0 | BC21: =IF(BB28=0,0,BB21/BB28) -> 0 | BD21: =BB21/12 -> 0 | BE21: =IF(BD21=0,"",RANK(BD21,BD$10:BD$27,0)) | BF21: =IF(BD21=0,"",IF(BE21=1,"er","ème"))
D22: =1+D21 -> 13 | E22: non | F22: Revenu à configurer | G22: - sélectionner - | AY22: =F22 -> Revenu à configurer | BB22: =SUM(I22:AR22) -> 0 | BC22: =IF(BB28=0,0,BB22/BB28) -> 0 | BD22: =BB22/12 -> 0 | BE22: =IF(BD22=0,"",RANK(BD22,BD$10:BD$27,0)) | BF22: =IF(BD22=0,"",IF(BE22=1,"er","ème"))
D23: =1+D22 -> 14 | E23: non | F23: Revenu à configurer | G23: - sélectionner - | AY23: =F23 -> Revenu à configurer | BB23: =SUM(I23:AR23) -> 0 | BC23: =IF(BB28=0,0,BB23/BB28) -> 0 | BD23: =BB23/12 -> 0 | BE23: =IF(BD23=0,"",RANK(BD23,BD$10:BD$27,0)) | BF23: =IF(BD23=0,"",IF(BE23=1,"er","ème"))
D24: =1+D23 -> 15 | E24: non | F24: Revenu à configurer | G24: - sélectionner - | AY24: =F24 -> Revenu à configurer | BB24: =SUM(I24:AR24) -> 0 | BC24: =IF(BB28=0,0,BB24/BB28) -> 0 | BD24: =BB24/12 -> 0 | BE24: =IF(BD24=0,"",RANK(BD24,BD$10:BD$27,0)) | BF24: =IF(BD24=0,"",IF(BE24=1,"er","ème"))
D25: =1+D24 -> 16 | E25: non | F25: Revenu à configurer | G25: - sélectionner - | AY25: =F25 -> Revenu à configurer | BB25: =SUM(I25:AR25) -> 0 | BC25: =IF(BB28=0,0,BB25/BB28) -> 0 | BD25: =BB25/12 -> 0 | BE25: =IF(BD25=0,"",RANK(BD25,BD$10:BD$27,0)) | BF25: =IF(BD25=0,"",IF(BE25=1,"er","ème"))
D26: =1+D25 -> 17 | E26: non | F26: Revenu à configurer | G26: - sélectionner - | AY26: =F26 -> Revenu à configurer | BB26: =SUM(I26:AR26) -> 0 | BC26: =IF(BB28=0,0,BB26/BB28) -> 0 | BD26: =BB26/12 -> 0 | BE26: =IF(BD26=0,"",RANK(BD26,BD$10:BD$27,0)) | BF26: =IF(BD26=0,"",IF(BE26=1,"er","ème"))
D27: =1+D26 -> 18 | E27: non | F27: Revenu à configurer | G27: - sélectionner - | AY27: =F27 -> Revenu à configurer | BB27: =SUM(I27:AR27) -> 0 | BC27: =IF(BB28=0,0,BB27/BB28) -> 0 | BD27: =BB27/12 -> 0 | BE27: =IF(BD27=0,"",RANK(BD27,BD$10:BD$27,0)) | BF27: =IF(BD27=0,"",IF(BE27=1,"er","ème"))
F28: TOTAL des REVENUS = | I28: =SUM(I10:J27) -> 3500 | L28: =SUM(L10:M27) -> 3500 | O28: =SUM(O10:P27) -> 3500 | R28: =SUM(R10:S27) -> 3500 | U28: =SUM(U10:V27) -> 3500 | X28: =SUM(X10:Y27) -> 3500 | AA28: =SUM(AA10:AB27) -> 3500 | AD28: =SUM(AD10:AE27) -> 3500 | AG28: =SUM(AG10:AH27) -> 3500 | AJ28: =SUM(AJ10:AK27) -> 3500 | AM28: =SUM(AM10:AN27) -> 3500 | AP28: =SUM(AP10:AQ27) -> 3500 | AY28: TOTAL Annuel des REVENUS = | BB28: =SUM(BB10:BB27) -> 42000
G29: Cumul des revenus mensuels = | I29: =I28 -> 3500 | L29: =I29+L28 -> 7000 | O29: =L29+O28 -> 10500 | R29: =O29+R28 -> 14000 | U29: =R29+U28 -> 17500 | X29: =U29+X28 -> 21000 | AA29: =X29+AA28 -> 24500 | AD29: =AA29+AD28 -> 28000 | AG29: =AD29+AG28 -> 31500 | AJ29: =AG29+AJ28 -> 35000 | AM29: =AJ29+AM28 -> 38500 | AP29: =AM29+AP28 -> 42000 | AZ29: Moyenne mensuelle des revenus = | BB29: =BB28/12 -> 3500
G30: Moy. mensuelle progressive = | I30: =I29 -> 3500 | L30: =L29/2 -> 3500 | O30: =O29/3 -> 3500 | R30: =R29/4 -> 3500 | U30: =U29/5 -> 3500 | X30: =X29/6 -> 3500 | AA30: =AA29/7 -> 3500 | AD30: =AD29/8 -> 3500 | AG30: =AG29/9 -> 3500 | AJ30: =AJ29/10 -> 3500 | AM30: =AM29/11 -> 3500 | AP30: =AP29/12 -> 3500
G32: Epargne/Placements/Provisions existantes rendues disponibles = | BA32: TOTAL annuel Epargne/Placements/Provisions existantes rendues dispo. = | BB32: =SUM(I32:AR32) -> 0
G34: TOTAL mensuel des RESSOURCES DISPONIBLES = | I34: =I28+I32 -> 3500 | L34: =L28+L32 -> 3500 | O34: =O28+O32 -> 3500 | R34: =R28+R32 -> 3500 | U34: =U28+U32 -> 3500 | X34: =X28+X32 -> 3500 | AA34: =AA28+AA32 -> 3500 | AD34: =AD28+AD32 -> 3500 | AG34: =AG28+AG32 -> 3500 | AJ34: =AJ28+AJ32 -> 3500 | AM34: =AM28+AM32 -> 3500 | AP34: =AP28+AP32 -> 3500 | BA34: TOTAL annuel des RESSOURCES DISPONIBLES = | BB34: =BB28+BB32 -> 42000
D37: Activé | E37: GRAND DISPATCHING | I37: =I7 -> 46174 | L37: =L7 -> 46206 | O37: =O7 -> 46238 | R37: =R7 -> 46270 | U37: =U7 -> 46302 | X37: =X7 -> 46334 | AA37: =AA7 -> 46366 | AD37: =AD7 -> 46398 | AG37: =AG7 -> 46430 | AJ37: =AJ7 -> 46462 | AM37: =AM7 -> 46494 | AP37: =AP7 -> 46526
E38: Equilibre dans les sections -> | I38: =IF($D$37="Désactivé","",CONCATENATE(IF(AND(I129>=0,I155>=0,I221>=0,I263>=0),"Sections équilibrées",CONCATENATE("Ajuster : ", IF(I129<0,"S1 ",""),IF(I155<0,"S2 ",""),IF(I222<0,"S3 ",""),IF(I263<0,"S4 ",""))))) -> Ajuster : S4 | L38: =IF($D$37="Désactivé","",CONCATENATE(IF(AND(L129>=0,L155>=0,L221>=0,L263>=0),"Sections équilibrées",CONCATENATE("Ajuster : ", IF(L129<0,"S1 ",""),IF(L155<0,"S2 ",""),IF(L222<0,"S3 ",""),IF(L263<0,"S4 ",""))))) -> Ajuster : S4 | O38: =IF($D$37="Désactivé","",CONCATENATE(IF(AND(O129>=0,O155>=0,O221>=0,O263>=0),"Sections équilibrées",CONCATENATE("Ajuster : ", IF(O129<0,"S1 ",""),IF(O155<0,"S2 ",""),IF(O222<0,"S3 ",""),IF(O263<0,"S4 ",""))))) -> Ajuster : S4 | R38: =IF($D$37="Désactivé","",CONCATENATE(IF(AND(R129>=0,R155>=0,R221>=0,R263>=0),"Sections équilibrées",CONCATENATE("Ajuster : ", IF(R129<0,"S1 ",""),IF(R155<0,"S2 ",""),IF(R222<0,"S3 ",""),IF(R263<0,"S4 ",""))))) -> Ajuster : S4 | U38: =IF($D$37="Désactivé","",CONCATENATE(IF(AND(U129>=0,U155>=0,U221>=0,U263>=0),"Sections équilibrées",CONCATENATE("Ajuster : ", IF(U129<0,"S1 ",""),IF(U155<0,"S2 ",""),IF(U222<0,"S3 ",""),IF(U263<0,"S4 ",""))))) -> Ajuster : S1 S3 S4 | X38: =IF($D$37="Désactivé","",CONCATENATE(IF(AND(X129>=0,X155>=0,X221>=0,X263>=0),"Sections équilibrées",CONCATENATE("Ajuster : ", IF(X129<0,"S1 ",""),IF(X155<0,"S2 ",""),IF(X222<0,"S3 ",""),IF(X263<0,"S4 ",""))))) -> Ajuster : S1 S3 S4 | AA38: =IF($D$37="Désactivé","",CONCATENATE(IF(AND(AA129>=0,AA155>=0,AA221>=0,AA263>=0),"Sections équilibrées",CONCATENATE("Ajuster : ", IF(AA129<0,"S1 ",""),IF(AA155<0,"S2 ",""),IF(AA222<0,"S3 ",""),IF(AA263<0,"S4 ",""))))) -> Ajuster : S1 S3 S4 | AD38: =IF($D$37="Désactivé","",CONCATENATE(IF(AND(AD129>=0,AD155>=0,AD221>=0,AD263>=0),"Sections équilibrées",CONCATENATE("Ajuster : ", IF(AD129<0,"S1 ",""),IF(AD155<0,"S2 ",""),IF(AD222<0,"S3 ",""),IF(AD263<0,"S4 ",""))))) -> Ajuster : S1 S3 S4 | AG38: =IF($D$37="Désactivé","",CONCATENATE(IF(AND(AG129>=0,AG155>=0,AG221>=0,AG263>=0),"Sections équilibrées",CONCATENATE("Ajuster : ", IF(AG129<0,"S1 ",""),IF(AG155<0,"S2 ",""),IF(AG222<0,"S3 ",""),IF(AG263<0,"S4 ",""))))) -> Ajuster : S1 S3 S4 | AJ38: =IF($D$37="Désactivé","",CONCATENATE(IF(AND(AJ129>=0,AJ155>=0,AJ221>=0,AJ263>=0),"Sections équilibrées",CONCATENATE("Ajuster : ", IF(AJ129<0,"S1 ",""),IF(AJ155<0,"S2 ",""),IF(AJ222<0,"S3 ",""),IF(AJ263<0,"S4 ",""))))) -> Ajuster : S1 S3 S4 | AM38: =IF($D$37="Désactivé","",CONCATENATE(IF(AND(AM129>=0,AM155>=0,AM221>=0,AM263>=0),"Sections équilibrées",CONCATENATE("Ajuster : ", IF(AM129<0,"S1 ",""),IF(AM155<0,"S2 ",""),IF(AM222<0,"S3 ",""),IF(AM263<0,"S4 ",""))))) -> Ajuster : S1 S3 S4 | AP38: =IF($D$37="Désactivé","",CONCATENATE(IF(AND(AP129>=0,AP155>=0,AP221>=0,AP263>=0),"Sections équilibrées",CONCATENATE("Ajuster : ", IF(AP129<0,"S1 ",""),IF(AP155<0,"S2 ",""),IF(AP222<0,"S3 ",""),IF(AP263<0,"S4 ",""))))) -> Ajuster : S1 S3 S4
E39: S1 | F39: Section EPARGNE & PLACEMENTS | I39: 1048 | K39: € | L39: 1048 | N39: € | O39: 1048 | Q39: € | R39: 1048 | T39: € | U39: 0 | W39: € | X39: 0 | Z39: % | AA39: 0 | AC39: % | AD39: 0 | AF39: % | AG39: 0 | AI39: % | AJ39: 0 | AL39: % | AM39: 0 | AO39: % | AP39: 0 | AR39: %
E41: S2 | F41: Section DETTES & CREDITS | I41: 0 | K41: € | L41: 0 | N41: € | O41: 0 | Q41: € | R41: 0 | T41: € | U41: 0 | W41: % | X41: 0 | Z41: € | AA41: 0 | AC41: € | AD41: 0 | AF41: € | AG41: 0 | AI41: € | AJ41: 0 | AL41: € | AM41: 0 | AO41: € | AP41: 0 | AR41: €
E43: S3 | F43: Section RESERVES & PROVISIONS | I43: 3010 | K43: € | L43: 3010 | N43: € | O43: 3010 | Q43: € | R43: 3010 | T43: € | U43: 0 | W43: € | X43: 0 | Z43: % | AA43: 0 | AC43: % | AD43: 0 | AF43: % | AG43: 0 | AI43: % | AJ43: 0 | AL43: % | AM43: 0 | AO43: % | AP43: 0 | AR43: %
E45: S4 | F45: Section CHARGES & DEPENSES COURANTES | I45: 1031.3 | K45: € | L45: 1031.3 | N45: € | O45: 1031.3 | Q45: € | R45: 1031.3 | T45: € | U45: 0 | W45: € | X45: 0 | Z45: € | AA45: 0 | AC45: € | AD45: 0 | AF45: € | AG45: 0 | AI45: € | AJ45: 0 | AL45: € | AM45: 0 | AO45: € | AP45: 0 | AR45: %
F47: REGULATEUR de DISPATCHING - Ajuster jusqu'à atteindre "0" (VERT) | I47: =INT((I28+I32)-SUM(IF(K39="€",I39,(I39*(I28+I32))/100),IF(K41="€",I41,(I41*(I28+I32))/100),IF(K43="€",I43,(I43*(I28+I32))/100),IF(K45="€",I45,(I45*(I28+I32))/100))) -> -1590 | L47: =INT((L28+L32)-SUM(IF(N39="€",L39,(L39*(L28+L32))/100),IF(N41="€",L41,(L41*(L28+L32))/100),IF(N43="€",L43,(L43*(L28+L32))/100),IF(N45="€",L45,(L45*(L28+L32))/100))) -> -1590 | O47: =INT((O28+O32)-SUM(IF(Q39="€",O39,(O39*(O28+O32))/100),IF(Q41="€",O41,(O41*(O28+O32))/100),IF(Q43="€",O43,(O43*(O28+O32))/100),IF(Q45="€",O45,(O45*(O28+O32))/100))) -> -1590 | R47: =INT((R28+R32)-SUM(IF(T39="€",R39,(R39*(R28+R32))/100),IF(T41="€",R41,(R41*(R28+R32))/100),IF(T43="€",R43,(R43*(R28+R32))/100),IF(T45="€",R45,(R45*(R28+R32))/100))) -> -1590 | U47: =INT((U28+U32)-SUM(IF(W39="€",U39,(U39*(U28+U32))/100),IF(W41="€",U41,(U41*(U28+U32))/100),IF(W43="€",U43,(U43*(U28+U32))/100),IF(W45="€",U45,(U45*(U28+U32))/100))) -> 3500 | X47: =INT((X28+X32)-SUM(IF(Z39="€",X39,(X39*(X28+X32))/100),IF(Z41="€",X41,(X41*(X28+X32))/100),IF(Z43="€",X43,(X43*(X28+X32))/100),IF(Z45="€",X45,(X45*(X28+X32))/100))) -> 3500 | AA47: =INT((AA28+AA32)-SUM(IF(AC39="€",AA39,(AA39*(AA28+AA32))/100),IF(AC41="€",AA41,(AA41*(AA28+AA32))/100),IF(AC43="€",AA43,(AA43*(AA28+AA32))/100),IF(AC45="€",AA45,(AA45*(AA28+AA32))/100))) -> 3500 | AD47: =INT((AD28+AD32)-SUM(IF(AF39="€",AD39,(AD39*(AD28+AD32))/100),IF(AF41="€",AD41,(AD41*(AD28+AD32))/100),IF(AF43="€",AD43,(AD43*(AD28+AD32))/100),IF(AF45="€",AD45,(AD45*(AD28+AD32))/100))) -> 3500 | AG47: =INT((AG28+AG32)-SUM(IF(AI39="€",AG39,(AG39*(AG28+AG32))/100),IF(AI41="€",AG41,(AG41*(AG28+AG32))/100),IF(AI43="€",AG43,(AG43*(AG28+AG32))/100),IF(AI45="€",AG45,(AG45*(AG28+AG32))/100))) -> 3500 | AJ47: =INT((AJ28+AJ32)-SUM(IF(AL39="€",AJ39,(AJ39*(AJ28+AJ32))/100),IF(AL41="€",AJ41,(AJ41*(AJ28+AJ32))/100),IF(AL43="€",AJ43,(AJ43*(AJ28+AJ32))/100),IF(AL45="€",AJ45,(AJ45*(AJ28+AJ32))/100))) -> 3500 | AM47: =INT((AM28+AM32)-SUM(IF(AO39="€",AM39,(AM39*(AM28+AM32))/100),IF(AO41="€",AM41,(AM41*(AM28+AM32))/100),IF(AO43="€",AM43,(AM43*(AM28+AM32))/100),IF(AO45="€",AM45,(AM45*(AM28+AM32))/100))) -> 3500 | AP47: =INT((AP28+AP32)-SUM(IF(AR39="€",AP39,(AP39*(AP28+AP32))/100),IF(AR41="€",AP41,(AP41*(AP28+AP32))/100),IF(AR43="€",AP43,(AP43*(AP28+AP32))/100),IF(AR45="€",AP45,(AP45*(AP28+AP32))/100))) -> 3500
D51: Mouvements d'épargne et de provisions | E51: S1 | F51: EPARGNE & PLACEMENTS | I51: =I7 -> 46174 | L51: =L7 -> 46206 | O51: =O7 -> 46238 | R51: =R7 -> 46270 | U51: =U7 -> 46302 | X51: =X7 -> 46334 | AA51: =AA7 -> 46366 | AD51: =AD7 -> 46398 | AG51: =AG7 -> 46430 | AJ51: =AJ7 -> 46462 | AM51: =AM7 -> 46494 | AP51: =AP7 -> 46526 | AT51: EXTRA | AU51: EXTRA | AY51: EPARGNE & PLACEMENTS
F52: =IF($D$37="Activé","Budgets mensuels disponibles pour l'épargne et les placements ->","Balances mensuelles ->") -> Budgets mensuels disponibles pour l'épargne et les placements -> | I52: =IF($D$37="Activé",IF(K39="%",INT(I39*I28/100),I39),I267) -> 1048 | L52: =IF($D$37="Activé",IF(N39="%",INT(L39*L28/100),L39),L267) -> 1048 | O52: =IF($D$37="Activé",IF(Q39="%",INT(O39*O28/100),O39),O267) -> 1048 | R52: =IF($D$37="Activé",IF(T39="%",INT(R39*R28/100),R39),R267) -> 1048 | U52: =IF($D$37="Activé",IF(W39="%",INT(U39*U28/100),U39),U267) -> 0 | X52: =IF($D$37="Activé",IF(Z39="%",INT(X39*X28/100),X39),X267) -> 0 | AA52: =IF($D$37="Activé",IF(AC39="%",INT(AA39*AA28/100),AA39),AA267) -> 0 | AD52: =IF($D$37="Activé",IF(AF39="%",INT(AD39*AD28/100),AD39),AD267) -> 0 | AG52: =IF($D$37="Activé",IF(AI39="%",INT(AG39*AG28/100),AG39),AG267) -> 0 | AJ52: =IF($D$37="Activé",IF(AL39="%",INT(AJ39*AJ28/100),AJ39),AJ267) -> 0 | AM52: =IF($D$37="Activé",IF(AO39="%",INT(AM39*AM28/100),AM39),AM267) -> 0 | AP52: =IF($D$37="Activé",IF(AR39="%",INT(AP39*AP28/100),AP39),AP267) -> 0 | AT52: PROJECTION | AU52: PROJECTION
E53: Configurez vos comptes d'épargne (en cliquant ici) | I53: Suivi | J53: Budget | L53: Suivi | M53: Budget | O53: Suivi | P53: Budget | R53: Suivi | S53: Budget | U53: Suivi | V53: Budget | X53: Suivi | Y53: Budget | AA53: Suivi | AB53: Budget | AD53: Suivi | AE53: Budget | AG53: Suivi | AH53: Budget | AJ53: Suivi | AK53: Budget | AM53: Suivi | AN53: Budget | AP53: Suivi | AQ53: Budget | AT53: Horizon 2 ans | AU53: Horizon 5 ans | AY53: Configurez vos comptes d'épargne (en cliquant ici) | BB53: Cumul annuel | BD53: Moy. mensuelle
...

Sheet Synthèse
A2: Retour au Budget
K4: =Menu!I6 -> Version 2026 Révision VMAX EUR
C6: Synthèse des mouvements sur vos comptes d'épargne et de provisions
D10: ='Budget Gold'!I7 -> 46174 | H10: ='Budget Gold'!L7 -> 46206 | L10: ='Budget Gold'!O7 -> 46238
D14: ='Budget Gold'!R7 -> 46270 | H14: ='Budget Gold'!U7 -> 46302 | L14: ='Budget Gold'!X7 -> 46334
D18: ='Budget Gold'!AA7 -> 46366 | H18: ='Budget Gold'!AD7 -> 46398 | L18: ='Budget Gold'!AG7 -> 46430
D22: ='Budget Gold'!AJ7 -> 46462 | H22: ='Budget Gold'!AM7 -> 46494 | L22: ='Budget Gold'!AP7 -> 46526

Sheet Menu Mariage
A2: Retour au MENU
D4: < Mariage Gold > | E4: =Menu!I6 -> Version 2026 Révision VMAX EUR
D5: Pour gérer le budget de votre cérémonie de mariage
D8: Prénom de la fiancée
D10: Prénom du fiancé
D12: Mois de démarrage du budget | E12: 46023
D14: Date prévisionnelle du mariage
D16: Mois/année de la cérémonie | E16: =IF(OR(E14="",E14="jj/mm/aaaa"),"",DATE(YEAR(E14),MONTH(E14),1))
C20: Accéder à Mariage Gold

Sheet Mariage
C2: < Mariage Gold > | E2: Budget Total prévisionnel | X2: Retour | Y2: PLAN DE FINANCEMENT prévisionnel | AH2: Retour | AI2: PLAN DES DECAISSEMENTS
A3: Accès au MENU | C3: =CONCATENATE('Menu Mariage'!E8," & ",'Menu Mariage'!E10) -> & | E3: =AD5 -> 0 | T3: =SUM(IF(T9="",0,E9), IF(T10="",0,E10), IF(T11="",0,E11), IF(T12="",0,E12), IF(T13="",0,E13), IF(T14="",0,E14), IF(T15="",0,E15), IF(T16="",0,E16), IF(T17="",0,E17), IF(T18="",0,E18), IF(T20="",0,E20), IF(T21="",0,E21), IF(T22="",0,E22), IF(T23="",0,E23), IF(T24="",0,E24), IF(T25="",0,E25), IF(T26="",0,E26), IF(T30="",0,E30), IF(T31="",0,E31), IF(T32="",0,E32), IF(T33="",0,E33), IF(T34="",0,E34), IF(T35="",0,E35), IF(T36="",0,E36), IF(T37="",0,E37), IF(T38="",0,E38), IF(T39="",0,E39), IF(T40="",0,E40), IF(T44="",0,E44), IF(T45="",0,E45), IF(T46="",0,E46), IF(T47="",0,E47), IF(T48="",0,E48), IF(T49="",0,E49), IF(T50="",0,E50), IF(T51="",0,E51), IF(T52="",0,E52), IF(T53="",0,E53), IF(T54="",0,E54), IF(T58="",0,E58), IF(T59="",0,E59), IF(T60="",0,E60), IF(T61="",0,E61), IF(T62="",0,E62), IF(T63="",0,E63), IF(T64="",0,E64), IF(T68="",0,E68), IF(T69="",0,E69), IF(T70="",0,E70)) -> 0 | V3: <--- Budget à financer (avec les prix courants et les priorités) | AF3: Différence
A5: Accès au Budget | C5: =IF(OR('Menu Mariage'!E14="",'Menu Mariage'!E14="jj/mm/aaaa"),"",CONCATENATE("Le ",DAY('Menu Mariage'!E14),"/",MONTH('Menu Mariage'!E14),"/",YEAR('Menu Mariage'!E14))) | E5: =E27+E41+E55+E65+E71 -> 0 | G5: =G27+G41+G55+G65+G71 -> 0 | L5: =Menu!I6 -> Version 2026 Révision VMAX EUR | Q5: Priorités | T5: =SUM(IF(T9="",0,G9), IF(T10="",0,G10), IF(T11="",0,G11), IF(T12="",0,G12), IF(T13="",0,G13), IF(T14="",0,G14), IF(T15="",0,G15), IF(T16="",0,G16), IF(T17="",0,G17), IF(T18="",0,G18), IF(T20="",0,G20), IF(T21="",0,G21), IF(T22="",0,G22), IF(T23="",0,G23), IF(T24="",0,G24), IF(T25="",0,G25), IF(T26="",0,G26), IF(T30="",0,G30), IF(T31="",0,G31), IF(T32="",0,G32), IF(T33="",0,G33), IF(T34="",0,G34), IF(T35="",0,G35), IF(T36="",0,G36), IF(T37="",0,G37), IF(T38="",0,G38), IF(T39="",0,G39), IF(T40="",0,G40), IF(T44="",0,G44), IF(T45="",0,G45), IF(T46="",0,G46), IF(T47="",0,G47), IF(T48="",0,G48), IF(T49="",0,G49), IF(T50="",0,G50), IF(T51="",0,G51), IF(T52="",0,G52), IF(T53="",0,G53), IF(T54="",0,G54), IF(T58="",0,G58), IF(T59="",0,G59), IF(T60="",0,G60), IF(T61="",0,G61), IF(T62="",0,G62), IF(T63="",0,G63), IF(T64="",0,G64), IF(T68="",0,G68), IF(T69="",0,G69), IF(T70="",0,G70)) -> 0 | V5: <--- Budget Réel à financer (avec les devis retenus et les priorités) | Y5: Remplir les lignes les unes après les autres sans sauter de ligne | AD5: =MAX(AD8:AD157) -> 0 | AE5: =MAX(AE8:AE157) -> 0 | AF5: =AE5-AD5 -> 0 | AJ5: Total de tous les paiements prévisionnels | AL5: Budget restant à couvrir pour effectuer tous les paiements | AM5: Total des paiements déjà réalisés | AN5: Budget Réel disponible (à ce jour)
A6: Simulateur d'épargne | E6: Frais à financer (Prix courants) | G6: Frais Réels à financer (avec les devis retenus) | Q6: =CONCATENATE(COUNTIF(Q9:Q70,"1 (indispensable)")," prio1, ",COUNTIF(Q9:Q70,"2 (essentiel)")," prio2 et ",COUNTIF(Q9:Q70," 3 (souhaitable)")," prio3") -> 0 prio1, 0 prio2 et 0 prio3 | R6: =CONCATENATE(COUNTIF(R9:R70,"1 (indispensable)")," prio1, ",COUNTIF(R9:R70,"2 (essentiel)")," prio2 et ",COUNTIF(R9:R70," 3 (souhaitable)")," prio3") -> 0 prio1, 0 prio2 et 0 prio3 | T6: Priorités combinées | Y6: Date | Z6: Montant de l'apport | AA6: Etat | AB6: Provenance (Qui apporte ?) | AC6: Type | AD6: Budget Total (prévisionnelles) | AE6: Budget Total (réelles)
C7: Préparation des mariés | J7: Devis 1 | L7: Devis 2 | N7: Devis 3 | Q7: =IF('Menu Mariage'!E8="","Priorités de la fiancée",CONCATENATE("Priorités de ",'Menu Mariage'!E8)) -> Priorités de la fiancée | R7: =IF('Menu Mariage'!E10="","Priorités du fiancé",CONCATENATE("Priorités de ",'Menu Mariage'!E10)) -> Priorités du fiancé | V7: Remarques/commentaires | AJ7: =0-SUM(AJ11:AJ160) -> 0 | AL7: =IF((0-AJ7)-AE5<0,0,(0-AJ7)-AE5) -> 0 | AM7: =SUM(AN11:AN160) -> 0 | AN7: =AE5-AM7 -> 0
A8: Configurer Mariage Gold | C8: Préparation de la mariée | X8: 1 | Y8: jj-mm-aaaa | AA8: Non effectué | AD8: =IF(Z8="","",Z8) | AE8: =IF(AA8="Non effectué","",Z8)
C9: Robe de la mariée | G9: =IF(H9="",IF(E9="","",E9),IF(H9="Devis 1",J9,IF(H9="Devis 2",L9,N9))) | K9: Voir | M9: Voir | O9: Voir | T9: =IF(OR(Q9="1 (indispensable)",R9="1 (indispensable)"),"1 (indispensable)",IF(AND(Q9="2 (essentiel)",R9="2 (essentiel)"),"2 (essentiel)","")) | X9: =1+X8 -> 2 | Y9: jj-mm-aaaa | AA9: Non effectué | AD9: =IF(Z9="","",Z9+AD8) | AE9: =IF(Z9="","",IF(AA9="Non effectué",IF(AE8="","",AE8),IF(AE8="",Z9,Z9+AE8))) | AI9: Date | AJ9: Montant du paiement | AK9: Etat | AL9: Prestations | AM9: Prestataires | AN9: Paiements réalisés
C10: Coiffure | G10: =IF(H10="",IF(E10="","",E10),IF(H10="Devis 1",J10,IF(H10="Devis 2",L10,N10))) | K10: Voir | M10: Voir | O10: Voir | T10: =IF(OR(Q10="1 (indispensable)",R10="1 (indispensable)"),"1 (indispensable)",IF(AND(Q10="2 (essentiel)",R10="2 (essentiel)"),"2 (essentiel)","")) | X10: =1+X9 -> 3 | Y10: jj-mm-aaaa | AA10: Non effectué | AD10: =IF(Z10="","",Z10+AD9) | AE10: =IF(Z10="","",IF(AA10="Non effectué",IF(AE9="","",AE9),IF(AE9="",Z10,Z10+AE9)))
A11: Plan de financement | C11: Maquillage | G11: =IF(H11="",IF(E11="","",E11),IF(H11="Devis 1",J11,IF(H11="Devis 2",L11,N11))) | K11: Voir | M11: Voir | O11: Voir | T11: =IF(OR(Q11="1 (indispensable)",R11="1 (indispensable)"),"1 (indispensable)",IF(AND(Q11="2 (essentiel)",R11="2 (essentiel)"),"2 (essentiel)","")) | X11: =1+X10 -> 4 | Y11: jj-mm-aaaa | AA11: Non effectué | AD11: =IF(Z11="","",Z11+AD10) | AE11: =IF(Z11="","",IF(AA11="Non effectué",IF(AE10="","",AE10),IF(AE10="",Z11,Z11+AE10))) | AH11: 1 | AI11: jj-mm-aaaa | AK11: Non effectué | AL11: Ex: Acompte salle de réception | AM11: EVENT-LOCATION | AN11: =IF(AK11="Non effectué","",AJ11)
C12: Esthéticienne/Pédicure | G12: =IF(H12="",IF(E12="","",E12),IF(H12="Devis 1",J12,IF(H12="Devis 2",L12,N12))) | K12: Voir | M12: Voir | O12: Voir | T12: =IF(OR(Q12="1 (indispensable)",R12="1 (indispensable)"),"1 (indispensable)",IF(AND(Q12="2 (essentiel)",R12="2 (essentiel)"),"2 (essentiel)","")) | X12: =1+X11 -> 5 | Y12: jj-mm-aaaa | AA12: Non effectué | AD12: =IF(Z12="","",Z12+AD11) | AE12: =IF(Z12="","",IF(AA12="Non effectué",IF(AE11="","",AE11),IF(AE11="",Z12,Z12+AE11))) | AH12: =1+AH11 -> 2 | AI12: jj-mm-aaaa | AK12: Non effectué | AN12: =IF(AK12="Non effectué","",AJ12)
A13: Plan de décaissement | C13: Bouquet de la mariée | G13: =IF(H13="",IF(E13="","",E13),IF(H13="Devis 1",J13,IF(H13="Devis 2",L13,N13))) | K13: Voir | M13: Voir | O13: Voir | T13: =IF(OR(Q13="1 (indispensable)",R13="1 (indispensable)"),"1 (indispensable)",IF(AND(Q13="2 (essentiel)",R13="2 (essentiel)"),"2 (essentiel)","")) | X13: =1+X12 -> 6 | Y13: jj-mm-aaaa | AA13: Non effectué | AD13: =IF(Z13="","",Z13+AD12) | AE13: =IF(Z13="","",IF(AA13="Non effectué",IF(AE12="","",AE12),IF(AE12="",Z13,Z13+AE12))) | AH13: =1+AH12 -> 3 | AI13: jj-mm-aaaa | AK13: Non effectué | AN13: =IF(AK13="Non effectué","",AJ13)
C14: Accessoires de la mariée | G14: =IF(H14="",IF(E14="","",E14),IF(H14="Devis 1",J14,IF(H14="Devis 2",L14,N14))) | K14: Voir | M14: Voir | O14: Voir | T14: =IF(OR(Q14="1 (indispensable)",R14="1 (indispensable)"),"1 (indispensable)",IF(AND(Q14="2 (essentiel)",R14="2 (essentiel)"),"2 (essentiel)","")) | X14: =1+X13 -> 7 | Y14: jj-mm-aaaa | AA14: Non effectué | AD14: =IF(Z14="","",Z14+AD13) | AE14: =IF(Z14="","",IF(AA14="Non effectué",IF(AE13="","",AE13),IF(AE13="",Z14,Z14+AE13))) | AH14: =1+AH13 -> 4 | AI14: jj-mm-aaaa | AK14: Non effectué | AN14: =IF(AK14="Non effectué","",AJ14)
C15: Tenue de soirée | G15: =IF(H15="",IF(E15="","",E15),IF(H15="Devis 1",J15,IF(H15="Devis 2",L15,N15))) | K15: Voir | M15: Voir | O15: Voir | T15: =IF(OR(Q15="1 (indispensable)",R15="1 (indispensable)"),"1 (indispensable)",IF(AND(Q15="2 (essentiel)",R15="2 (essentiel)"),"2 (essentiel)","")) | X15: =1+X14 -> 8 | Y15: jj-mm-aaaa | AA15: Non effectué | AD15: =IF(Z15="","",Z15+AD14) | AE15: =IF(Z15="","",IF(AA15="Non effectué",IF(AE14="","",AE14),IF(AE14="",Z15,Z15+AE14))) | AH15: =1+AH14 -> 5 | AI15: jj-mm-aaaa | AK15: Non effectué | AN15: =IF(AK15="Non effectué","",AJ15)
C16: Autre (1) | G16: =IF(H16="",IF(E16="","",E16),IF(H16="Devis 1",J16,IF(H16="Devis 2",L16,N16))) | K16: Voir | M16: Voir | O16: Voir | T16: =IF(OR(Q16="1 (indispensable)",R16="1 (indispensable)"),"1 (indispensable)",IF(AND(Q16="2 (essentiel)",R16="2 (essentiel)"),"2 (essentiel)","")) | X16: =1+X15 -> 9 | Y16: jj-mm-aaaa | AA16: Non effectué | AD16: =IF(Z16="","",Z16+AD15) | AE16: =IF(Z16="","",IF(AA16="Non effectué",IF(AE15="","",AE15),IF(AE15="",Z16,Z16+AE15))) | AH16: =1+AH15 -> 6 | AI16: jj-mm-aaaa | AK16: Non effectué | AN16: =IF(AK16="Non effectué","",AJ16)
C17: Autre (2) | G17: =IF(H17="",IF(E17="","",E17),IF(H17="Devis 1",J17,IF(H17="Devis 2",L17,N17))) | K17: Voir | M17: Voir | O17: Voir | T17: =IF(OR(Q17="1 (indispensable)",R17="1 (indispensable)"),"1 (indispensable)",IF(AND(Q17="2 (essentiel)",R17="2 (essentiel)"),"2 (essentiel)","")) | X17: =1+X16 -> 10 | Y17: jj-mm-aaaa | AA17: Non effectué | AD17: =IF(Z17="","",Z17+AD16) | AE17: =IF(Z17="","",IF(AA17="Non effectué",IF(AE16="","",AE16),IF(AE16="",Z17,Z17+AE16))) | AH17: =1+AH16 -> 7 | AI17: jj-mm-aaaa | AK17: Non effectué | AN17: =IF(AK17="Non effectué","",AJ17)
C18: Autre (3) | G18: =IF(H18="",IF(E18="","",E18),IF(H18="Devis 1",J18,IF(H18="Devis 2",L18,N18))) | K18: Voir | M18: Voir | O18: Voir | T18: =IF(OR(Q18="1 (indispensable)",R18="1 (indispensable)"),"1 (indispensable)",IF(AND(Q18="2 (essentiel)",R18="2 (essentiel)"),"2 (essentiel)","")) | X18: =1+X17 -> 11 | Y18: jj-mm-aaaa | AA18: Non effectué | AD18: =IF(Z18="","",Z18+AD17) | AE18: =IF(Z18="","",IF(AA18="Non effectué",IF(AE17="","",AE17),IF(AE17="",Z18,Z18+AE17))) | AH18: =1+AH17 -> 8 | AI18: jj-mm-aaaa | AK18: Non effectué | AN18: =IF(AK18="Non effectué","",AJ18)
C19: Préparation du marié | X19: =1+X18 -> 12 | Y19: jj-mm-aaaa | AA19: Non effectué | AD19: =IF(Z19="","",Z19+AD18) | AE19: =IF(Z19="","",IF(AA19="Non effectué",IF(AE18="","",AE18),IF(AE18="",Z19,Z19+AE18))) | AH19: =1+AH18 -> 9 | AI19: jj-mm-aaaa | AK19: Non effectué | AN19: =IF(AK19="Non effectué","",AJ19)
C20: Tenue du marié | G20: =IF(H20="",IF(E20="","",E20),IF(H20="Devis 1",J20,IF(H20="Devis 2",L20,N20))) | K20: Voir | M20: Voir | O20: Voir | T20: =IF(OR(Q20="1 (indispensable)",R20="1 (indispensable)"),"1 (indispensable)",IF(AND(Q20="2 (essentiel)",R20="2 (essentiel)"),"2 (essentiel)","")) | X20: =1+X19 -> 13 | Y20: jj-mm-aaaa | AA20: Non effectué | AD20: =IF(Z20="","",Z20+AD19) | AE20: =IF(Z20="","",IF(AA20="Non effectué",IF(AE19="","",AE19),IF(AE19="",Z20,Z20+AE19))) | AH20: =1+AH19 -> 10 | AI20: jj-mm-aaaa | AK20: Non effectué | AN20: =IF(AK20="Non effectué","",AJ20)
C21: Accessoires du marié | G21: =IF(H21="",IF(E21="","",E21),IF(H21="Devis 1",J21,IF(H21="Devis 2",L21,N21))) | K21: Voir | M21: Voir | O21: Voir | T21: =IF(OR(Q21="1 (indispensable)",R21="1 (indispensable)"),"1 (indispensable)",IF(AND(Q21="2 (essentiel)",R21="2 (essentiel)"),"2 (essentiel)","")) | X21: =1+X20 -> 14 | Y21: jj-mm-aaaa | AA21: Non effectué | AD21: =IF(Z21="","",Z21+AD20) | AE21: =IF(Z21="","",IF(AA21="Non effectué",IF(AE20="","",AE20),IF(AE20="",Z21,Z21+AE20))) | AH21: =1+AH20 -> 11 | AI21: jj-mm-aaaa | AK21: Non effectué | AN21: =IF(AK21="Non effectué","",AJ21)
C22: Coiffure | G22: =IF(H22="",IF(E22="","",E22),IF(H22="Devis 1",J22,IF(H22="Devis 2",L22,N22))) | K22: Voir | M22: Voir | O22: Voir | T22: =IF(OR(Q22="1 (indispensable)",R22="1 (indispensable)"),"1 (indispensable)",IF(AND(Q22="2 (essentiel)",R22="2 (essentiel)"),"2 (essentiel)","")) | X22: =1+X21 -> 15 | Y22: jj-mm-aaaa | AA22: Non effectué | AD22: =IF(Z22="","",Z22+AD21) | AE22: =IF(Z22="","",IF(AA22="Non effectué",IF(AE21="","",AE21),IF(AE21="",Z22,Z22+AE21))) | AH22: =1+AH21 -> 12 | AI22: jj-mm-aaaa | AK22: Non effectué | AN22: =IF(AK22="Non effectué","",AJ22)
C23: Tenue de soirée | G23: =IF(H23="",IF(E23="","",E23),IF(H23="Devis 1",J23,IF(H23="Devis 2",L23,N23))) | K23: Voir | M23: Voir | O23: Voir | T23: =IF(OR(Q23="1 (indispensable)",R23="1 (indispensable)"),"1 (indispensable)",IF(AND(Q23="2 (essentiel)",R23="2 (essentiel)"),"2 (essentiel)","")) | X23: =1+X22 -> 16 | Y23: jj-mm-aaaa | AA23: Non effectué | AD23: =IF(Z23="","",Z23+AD22) | AE23: =IF(Z23="","",IF(AA23="Non effectué",IF(AE22="","",AE22),IF(AE22="",Z23,Z23+AE22))) | AH23: =1+AH22 -> 13 | AI23: jj-mm-aaaa | AK23: Non effectué | AN23: =IF(AK23="Non effectué","",AJ23)
C24: Autre (1) | G24: =IF(H24="",IF(E24="","",E24),IF(H24="Devis 1",J24,IF(H24="Devis 2",L24,N24))) | K24: Voir | M24: Voir | O24: Voir | T24: =IF(OR(Q24="1 (indispensable)",R24="1 (indispensable)"),"1 (indispensable)",IF(AND(Q24="2 (essentiel)",R24="2 (essentiel)"),"2 (essentiel)","")) | X24: =1+X23 -> 17 | Y24: jj-mm-aaaa | AA24: Non effectué | AD24: =IF(Z24="","",Z24+AD23) | AE24: =IF(Z24="","",IF(AA24="Non effectué",IF(AE23="","",AE23),IF(AE23="",Z24,Z24+AE23))) | AH24: =1+AH23 -> 14 | AI24: jj-mm-aaaa | AK24: Non effectué | AN24: =IF(AK24="Non effectué","",AJ24)
C25: Autre (2) | G25: =IF(H25="",IF(E25="","",E25),IF(H25="Devis 1",J25,IF(H25="Devis 2",L25,N25))) | K25: Voir | M25: Voir | O25: Voir | T25: =IF(OR(Q25="1 (indispensable)",R25="1 (indispensable)"),"1 (indispensable)",IF(AND(Q25="2 (essentiel)",R25="2 (essentiel)"),"2 (essentiel)","")) | X25: =1+X24 -> 18 | Y25: jj-mm-aaaa | AA25: Non effectué | AD25: =IF(Z25="","",Z25+AD24) | AE25: =IF(Z25="","",IF(AA25="Non effectué",IF(AE24="","",AE24),IF(AE24="",Z25,Z25+AE24))) | AH25: =1+AH24 -> 15 | AI25: jj-mm-aaaa | AK25: Non effectué | AN25: =IF(AK25="Non effectué","",AJ25)
C26: Autre (3) | G26: =IF(H26="",IF(E26="","",E26),IF(H26="Devis 1",J26,IF(H26="Devis 2",L26,N26))) | K26: Voir | M26: Voir | O26: Voir | T26: =IF(OR(Q26="1 (indispensable)",R26="1 (indispensable)"),"1 (indispensable)",IF(AND(Q26="2 (essentiel)",R26="2 (essentiel)"),"2 (essentiel)","")) | X26: =1+X25 -> 19 | Y26: jj-mm-aaaa | AA26: Non effectué | AD26: =IF(Z26="","",Z26+AD25) | AE26: =IF(Z26="","",IF(AA26="Non effectué",IF(AE25="","",AE25),IF(AE25="",Z26,Z26+AE25))) | AH26: =1+AH25 -> 16 | AI26: jj-mm-aaaa | AK26: Non effectué | AN26: =IF(AK26="Non effectué","",AJ26)
C27: sous-total = | E27: =SUM(E9:E26) -> 0 | G27: =SUM(G9:G26) -> 0 | J27: =SUM(J9:J26) -> 0 | L27: =SUM(L9:L26) -> 0 | N27: =SUM(N9:N26) -> 0 | X27: =1+X26 -> 20 | Y27: jj-mm-aaaa | AA27: Non effectué | AD27: =IF(Z27="","",Z27+AD26) | AE27: =IF(Z27="","",IF(AA27="Non effectué",IF(AE26="","",AE26),IF(AE26="",Z27,Z27+AE26))) | AH27: =1+AH26 -> 17 | AI27: jj-mm-aaaa | AK27: Non effectué | AN27: =IF(AK27="Non effectué","",AJ27)
X28: =1+X27 -> 21 | Y28: jj-mm-aaaa | AA28: Non effectué | AD28: =IF(Z28="","",Z28+AD27) | AE28: =IF(Z28="","",IF(AA28="Non effectué",IF(AE27="","",AE27),IF(AE27="",Z28,Z28+AE27))) | AH28: =1+AH27 -> 18 | AI28: jj-mm-aaaa | AK28: Non effectué | AN28: =IF(AK28="Non effectué","",AJ28)
C29: Cérémonies | E29: Frais à financer | G29: Frais réels à financer | J29: Devis 1 | L29: Devis 2 | N29: Devis 3 | Q29: =Q7 -> Priorités de la fiancée | R29: =R7 -> Priorités du fiancé | T29: Priorités combinées | V29: Remarques/commentaires | X29: =1+X28 -> 22 | Y29: jj-mm-aaaa | AA29: Non effectué | AD29: =IF(Z29="","",Z29+AD28) | AE29: =IF(Z29="","",IF(AA29="Non effectué",IF(AE28="","",AE28),IF(AE28="",Z29,Z29+AE28))) | AH29: =1+AH28 -> 19 | AI29: jj-mm-aaaa | AK29: Non effectué | AN29: =IF(AK29="Non effectué","",AJ29)
C30: Alliances | G30: =IF(H30="",IF(E30="","",E30),IF(H30="Devis 1",J30,IF(H30="Devis 2",L30,N30))) | K30: Voir | M30: Voir | O30: Voir | T30: =IF(OR(Q30="1 (indispensable)",R30="1 (indispensable)"),"1 (indispensable)",IF(AND(Q30="2 (essentiel)",R30="2 (essentiel)"),"2 (essentiel)","")) | X30: =1+X29 -> 23 | Y30: jj-mm-aaaa | AA30: Non effectué | AD30: =IF(Z30="","",Z30+AD29) | AE30: =IF(Z30="","",IF(AA30="Non effectué",IF(AE29="","",AE29),IF(AE29="",Z30,Z30+AE29))) | AH30: =1+AH29 -> 20 | AI30: jj-mm-aaaa | AK30: Non effectué | AN30: =IF(AK30="Non effectué","",AJ30)
C31: Décoration Eglise | G31: =IF(H31="",IF(E31="","",E31),IF(H31="Devis 1",J31,IF(H31="Devis 2",L31,N31))) | K31: Voir | M31: Voir | O31: Voir | T31: =IF(OR(Q31="1 (indispensable)",R31="1 (indispensable)"),"1 (indispensable)",IF(AND(Q31="2 (essentiel)",R31="2 (essentiel)"),"2 (essentiel)","")) | X31: =1+X30 -> 24 | Y31: jj-mm-aaaa | AA31: Non effectué | AD31: =IF(Z31="","",Z31+AD30) | AE31: =IF(Z31="","",IF(AA31="Non effectué",IF(AE30="","",AE30),IF(AE30="",Z31,Z31+AE30))) | AH31: =1+AH30 -> 21 | AI31: jj-mm-aaaa | AK31: Non effectué | AN31: =IF(AK31="Non effectué","",AJ31)
C32: Animation de la sortie (riz, pétales, confettis..) | G32: =IF(H32="",IF(E32="","",E32),IF(H32="Devis 1",J32,IF(H32="Devis 2",L32,N32))) | K32: Voir | M32: Voir | O32: Voir | T32: =IF(OR(Q32="1 (indispensable)",R32="1 (indispensable)"),"1 (indispensable)",IF(AND(Q32="2 (essentiel)",R32="2 (essentiel)"),"2 (essentiel)","")) | X32: =1+X31 -> 25 | Y32: jj-mm-aaaa | AA32: Non effectué | AD32: =IF(Z32="","",Z32+AD31) | AE32: =IF(Z32="","",IF(AA32="Non effectué",IF(AE31="","",AE31),IF(AE31="",Z32,Z32+AE31))) | AH32: =1+AH31 -> 22 | AI32: jj-mm-aaaa | AK32: Non effectué | AN32: =IF(AK32="Non effectué","",AJ32)
C33: Offrande (église) | G33: =IF(H33="",IF(E33="","",E33),IF(H33="Devis 1",J33,IF(H33="Devis 2",L33,N33))) | K33: Voir | M33: Voir | O33: Voir | T33: =IF(OR(Q33="1 (indispensable)",R33="1 (indispensable)"),"1 (indispensable)",IF(AND(Q33="2 (essentiel)",R33="2 (essentiel)"),"2 (essentiel)","")) | X33: =1+X32 -> 26 | Y33: jj-mm-aaaa | AA33: Non effectué | AD33: =IF(Z33="","",Z33+AD32) | AE33: =IF(Z33="","",IF(AA33="Non effectué",IF(AE32="","",AE32),IF(AE32="",Z33,Z33+AE32))) | AH33: =1+AH32 -> 23 | AI33: jj-mm-aaaa | AK33: Non effectué | AN33: =IF(AK33="Non effectué","",AJ33)
C34: Location de la voiture des mariés | G34: =IF(H34="",IF(E34="","",E34),IF(H34="Devis 1",J34,IF(H34="Devis 2",L34,N34))) | K34: Voir | M34: Voir | O34: Voir | T34: =IF(OR(Q34="1 (indispensable)",R34="1 (indispensable)"),"1 (indispensable)",IF(AND(Q34="2 (essentiel)",R34="2 (essentiel)"),"2 (essentiel)","")) | X34: =1+X33 -> 27 | Y34: jj-mm-aaaa | AA34: Non effectué | AD34: =IF(Z34="","",Z34+AD33) | AE34: =IF(Z34="","",IF(AA34="Non effectué",IF(AE33="","",AE33),IF(AE33="",Z34,Z34+AE33))) | AH34: =1+AH33 -> 24 | AI34: jj-mm-aaaa | AK34: Non effectué | AN34: =IF(AK34="Non effectué","",AJ34)
C35: Location autres véhicules | G35: =IF(H35="",IF(E35="","",E35),IF(H35="Devis 1",J35,IF(H35="Devis 2",L35,N35))) | K35: Voir | M35: Voir | O35: Voir | T35: =IF(OR(Q35="1 (indispensable)",R35="1 (indispensable)"),"1 (indispensable)",IF(AND(Q35="2 (essentiel)",R35="2 (essentiel)"),"2 (essentiel)","")) | X35: =1+X34 -> 28 | Y35: jj-mm-aaaa | AA35: Non effectué | AD35: =IF(Z35="","",Z35+AD34) | AE35: =IF(Z35="","",IF(AA35="Non effectué",IF(AE34="","",AE34),IF(AE34="",Z35,Z35+AE34))) | AH35: =1+AH34 -> 25 | AI35: jj-mm-aaaa | AK35: Non effectué | AN35: =IF(AK35="Non effectué","",AJ35)
C36: Photographe | G36: =IF(H36="",IF(E36="","",E36),IF(H36="Devis 1",J36,IF(H36="Devis 2",L36,N36))) | K36: Voir | M36: Voir | O36: Voir | T36: =IF(OR(Q36="1 (indispensable)",R36="1 (indispensable)"),"1 (indispensable)",IF(AND(Q36="2 (essentiel)",R36="2 (essentiel)"),"2 (essentiel)","")) | X36: =1+X35 -> 29 | Y36: jj-mm-aaaa | AA36: Non effectué | AD36: =IF(Z36="","",Z36+AD35) | AE36: =IF(Z36="","",IF(AA36="Non effectué",IF(AE35="","",AE35),IF(AE35="",Z36,Z36+AE35))) | AH36: =1+AH35 -> 26 | AI36: jj-mm-aaaa | AK36: Non effectué | AN36: =IF(AK36="Non effectué","",AJ36)
C37: Caméraman | G37: =IF(H37="",IF(E37="","",E37),IF(H37="Devis 1",J37,IF(H37="Devis 2",L37,N37))) | K37: Voir | M37: Voir | O37: Voir | T37: =IF(OR(Q37="1 (indispensable)",R37="1 (indispensable)"),"1 (indispensable)",IF(AND(Q37="2 (essentiel)",R37="2 (essentiel)"),"2 (essentiel)","")) | X37: =1+X36 -> 30 | Y37: jj-mm-aaaa | AA37: Non effectué | AD37: =IF(Z37="","",Z37+AD36) | AE37: =IF(Z37="","",IF(AA37="Non effectué",IF(AE36="","",AE36),IF(AE36="",Z37,Z37+AE36))) | AH37: =1+AH36 -> 27 | AI37: jj-mm-aaaa | AK37: Non effectué | AN37: =IF(AK37="Non effectué","",AJ37)
C38: Autre (1) | G38: =IF(H38="",IF(E38="","",E38),IF(H38="Devis 1",J38,IF(H38="Devis 2",L38,N38))) | K38: Voir | M38: Voir | O38: Voir | T38: =IF(OR(Q38="1 (indispensable)",R38="1 (indispensable)"),"1 (indispensable)",IF(AND(Q38="2 (essentiel)",R38="2 (essentiel)"),"2 (essentiel)","")) | X38: =1+X37 -> 31 | Y38: jj-mm-aaaa | AA38: Non effectué | AD38: =IF(Z38="","",Z38+AD37) | AE38: =IF(Z38="","",IF(AA38="Non effectué",IF(AE37="","",AE37),IF(AE37="",Z38,Z38+AE37))) | AH38: =1+AH37 -> 28 | AI38: jj-mm-aaaa | AK38: Non effectué | AN38: =IF(AK38="Non effectué","",AJ38)
C39: Autre (2) | G39: =IF(H39="",IF(E39="","",E39),IF(H39="Devis 1",J39,IF(H39="Devis 2",L39,N39))) | K39: Voir | M39: Voir | O39: Voir | T39: =IF(OR(Q39="1 (indispensable)",R39="1 (indispensable)"),"1 (indispensable)",IF(AND(Q39="2 (essentiel)",R39="2 (essentiel)"),"2 (essentiel)","")) | X39: =1+X38 -> 32 | Y39: jj-mm-aaaa | AA39: Non effectué | AD39: =IF(Z39="","",Z39+AD38) | AE39: =IF(Z39="","",IF(AA39="Non effectué",IF(AE38="","",AE38),IF(AE38="",Z39,Z39+AE38))) | AH39: =1+AH38 -> 29 | AI39: jj-mm-aaaa | AK39: Non effectué | AN39: =IF(AK39="Non effectué","",AJ39)
C40: Autre (3) | G40: =IF(H40="",IF(E40="","",E40),IF(H40="Devis 1",J40,IF(H40="Devis 2",L40,N40))) | K40: Voir | M40: Voir | O40: Voir | T40: =IF(OR(Q40="1 (indispensable)",R40="1 (indispensable)"),"1 (indispensable)",IF(AND(Q40="2 (essentiel)",R40="2 (essentiel)"),"2 (essentiel)","")) | X40: =1+X39 -> 33 | Y40: jj-mm-aaaa | AA40: Non effectué | AD40: =IF(Z40="","",Z40+AD39) | AE40: =IF(Z40="","",IF(AA40="Non effectué",IF(AE39="","",AE39),IF(AE39="",Z40,Z40+AE39))) | AH40: =1+AH39 -> 30 | AI40: jj-mm-aaaa | AK40: Non effectué | AN40: =IF(AK40="Non effectué","",AJ40)
C41: sous-total = | E41: =SUM(E30:E40) -> 0 | G41: =SUM(G30:G40) -> 0 | J41: =SUM(J30:J40) -> 0 | L41: =SUM(L30:L40) -> 0 | N41: =SUM(N30:N40) -> 0 | X41: =1+X40 -> 34 | Y41: jj-mm-aaaa | AA41: Non effectué | AD41: =IF(Z41="","",Z41+AD40) | AE41: =IF(Z41="","",IF(AA41="Non effectué",IF(AE40="","",AE40),IF(AE40="",Z41,Z41+AE40))) | AH41: =1+AH40 -> 31 | AI41: jj-mm-aaaa | AK41: Non effectué | AN41: =IF(AK41="Non effectué","",AJ41)
X42: =1+X41 -> 35 | Y42: jj-mm-aaaa | AA42: Non effectué | AD42: =IF(Z42="","",Z42+AD41) | AE42: =IF(Z42="","",IF(AA42="Non effectué",IF(AE41="","",AE41),IF(AE41="",Z42,Z42+AE41))) | AH42: =1+AH41 -> 32 | AI42: jj-mm-aaaa | AK42: Non effectué | AN42: =IF(AK42="Non effectué","",AJ42)
...

Sheet Simulateur
A2: Retour au Budget | C2: Simulateur d'épargne
G5: =Menu!I6 -> Version 2026 Révision VMAX EUR
B6: Epargne mensuelle | D6: Rentabilité brute moyenne (%) | E6: Apport initial
B7: 100 | D7: 3 | E7: 0 | F7: <- Les champs modifiables sont en JAUNE
D9: En Euros (€)
C10: Années | D10: Valeur acquise | E10: Epargne cumulée | F10: Gain brut
C11: 1 | D11: =(12*$B$7+E7)*(1+$D$7/100) -> 1236 | E11: =12*$B$7+E7 -> 1200 | F11: =D11-E11 -> 36
C12: 2 | D12: =(((12*$B$7)+D11)*(1+$D$7/100)) -> 2509.08 | E12: =E11+(12*$B$7) -> 2400 | F12: =D12-E12 -> 109.08
C13: 3 | D13: =(((12*$B$7)+D12)*(1+$D$7/100)) -> 3820.3524 | E13: =E12+(12*$B$7) -> 3600 | F13: =D13-E13 -> 220.3524
C14: 4 | D14: =(((12*$B$7)+D13)*(1+$D$7/100)) -> 5170.963 | E14: =E13+(12*$B$7) -> 4800 | F14: =D14-E14 -> 370.96297
C15: 5 | D15: =(((12*$B$7)+D14)*(1+$D$7/100)) -> 6562.0919 | E15: =E14+(12*$B$7) -> 6000 | F15: =D15-E15 -> 562.09186
C16: 6 | D16: =(((12*$B$7)+D15)*(1+$D$7/100)) -> 7994.9546 | E16: =E15+(12*$B$7) -> 7200 | F16: =D16-E16 -> 794.95462
C17: 7 | D17: =(((12*$B$7)+D16)*(1+$D$7/100)) -> 9470.8033 | E17: =E16+(12*$B$7) -> 8400 | F17: =D17-E17 -> 1070.8033
C18: 8 | D18: =(((12*$B$7)+D17)*(1+$D$7/100)) -> 10990.927 | E18: =E17+(12*$B$7) -> 9600 | F18: =D18-E18 -> 1390.9274
C19: 9 | D19: =(((12*$B$7)+D18)*(1+$D$7/100)) -> 12556.655 | E19: =E18+(12*$B$7) -> 10800 | F19: =D19-E19 -> 1756.6552
C20: 10 | D20: =(((12*$B$7)+D19)*(1+$D$7/100)) -> 14169.355 | E20: =E19+(12*$B$7) -> 12000 | F20: =D20-E20 -> 2169.3548
C21: 11 | D21: =(((12*$B$7)+D20)*(1+$D$7/100)) -> 15830.435 | E21: =E20+(12*$B$7) -> 13200 | F21: =D21-E21 -> 2630.4355
C22: 12 | D22: =(((12*$B$7)+D21)*(1+$D$7/100)) -> 17541.349 | E22: =E21+(12*$B$7) -> 14400 | F22: =D22-E22 -> 3141.3485
C23: 13 | D23: =(((12*$B$7)+D22)*(1+$D$7/100)) -> 19303.589 | E23: =E22+(12*$B$7) -> 15600 | F23: =D23-E23 -> 3703.589
... C30: 20 | D30: =(((12*$B$7)+D29)*(1+$D$7/100)) -> 33211.783 | E30: =E29+(12*$B$7) -> 24000 | F30: =D30-E30 -> 9211.7829
C31: =1+C30 -> 21 | D31: =(((12*$B$7)+D30)*(1+$D$7/100)) -> 35444.136 | E31: =E30+(12*$B$7) -> 25200 | F31: =D31-E31 -> 10244.136
C32: =1+C31 -> 22 | D32: =(((12*$B$7)+D31)*(1+$D$7/100)) -> 37743.46 | E32: =E31+(12*$B$7) -> 26400 | F32: =D32-E32 -> 11343.46
C33: =1+C32 -> 23 | D33: =(((12*$B$7)+D32)*(1+$D$7/100)) -> 40111.764 | E33: =E32+(12*$B$7) -> 27600 | F33: =D33-E33 -> 12511.764
C34: =1+C33 -> 24 | D34: =(((12*$B$7)+D33)*(1+$D$7/100)) -> 42551.117 | E34: =E33+(12*$B$7) -> 28800 | F34: =D34-E34 -> 13751.117
C35: =1+C34 -> 25 | D35: =(((12*$B$7)+D34)*(1+$D$7/100)) -> 45063.651 | E35: =E34+(12*$B$7) -> 30000 | F35: =D35-E35 -> 15063.651
C36: =1+C35 -> 26 | D36: =(((12*$B$7)+D35)*(1+$D$7/100)) -> 47651.56 | E36: =E35+(12*$B$7) -> 31200 | F36: =D36-E36 -> 16451.56
C37: =1+C36 -> 27 | D37: =(((12*$B$7)+D36)*(1+$D$7/100)) -> 50317.107 | E37: =E36+(12*$B$7) -> 32400 | F37: =D37-E37 -> 17917.107
C38: =1+C37 -> 28 | D38: =(((12*$B$7)+D37)*(1+$D$7/100)) -> 53062.62 | E38: =E37+(12*$B$7) -> 33600 | F38: =D38-E38 -> 19462.62
C39: =1+C38 -> 29 | D39: =(((12*$B$7)+D38)*(1+$D$7/100)) -> 55890.499 | E39: =E38+(12*$B$7) -> 34800 | F39: =D39-E39 -> 21090.499
C40: =1+C39 -> 30 | D40: =(((12*$B$7)+D39)*(1+$D$7/100)) -> 58803.214 | E40: =E39+(12*$B$7) -> 36000 | F40: =D40-E40 -> 22803.214
C41: Années | D41: Valeur acquise | E41: Epargne cumulée | F41: Gain brut
D42: En Euros (€)

Sheet ImmoView 1
A2: Accès au MENU | C2: < ImmoView > | D2: Bien n° 1 | AP2: < ImmoView >
A3: Accès au Budget
A4: Simulateur d'épargne | C4: Désignation du bien | J4: =Menu!I6 -> Version 2026 Révision VMAX EUR
C5: Adresse
C6: Code postal - VILLE
C8: ENTREES | D8: =Menu!F22 -> 46174 | G8: =D8+32 -> 46206 | J8: =G8+32 -> 46238 | M8: =J8+32 -> 46270 | P8: =M8+32 -> 46302 | S8: =P8+32 -> 46334 | V8: =S8+32 -> 46366 | Y8: =V8+32 -> 46398 | AB8: =Y8+32 -> 46430 | AE8: =AB8+32 -> 46462 | AH8: =AE8+32 -> 46494 | AK8: =AH8+32 -> 46526 | AP8: ENTREES | AQ8: BILAN ANNUEL
D9: Suivi | E9: Budget | G9: Suivi | H9: Budget | J9: Suivi | K9: Budget | M9: Suivi | N9: Budget | P9: Suivi | Q9: Budget | S9: Suivi | T9: Budget | V9: Suivi | W9: Budget | Y9: Suivi | Z9: Budget | AB9: Suivi | AC9: Budget | AE9: Suivi | AF9: Budget | AH9: Suivi | AI9: Budget | AK9: Suivi | AL9: Budget
C10: Loyers | AP10: =C10 -> Loyers | AQ10: =SUM(MAX(D10:E10),MAX(G10:H10),MAX(J10:K10),MAX(M10,N10),MAX(P10:Q10),MAX(S10:T10),MAX(V10:W10),MAX(Y10:Z10),MAX(AB10:AC10),MAX(AE10,AF10),MAX(AH10:AI10),MAX(AK10:AL10)) -> 0
C11: Provisions pour charges | AP11: =C11 -> Provisions pour charges | AQ11: =SUM(MAX(D11:E11),MAX(G11:H11),MAX(J11:K11),MAX(M11,N11),MAX(P11:Q11),MAX(S11:T11),MAX(V11:W11),MAX(Y11:Z11),MAX(AB11:AC11),MAX(AE11,AF11),MAX(AH11:AI11),MAX(AK11:AL11)) -> 0
C12: Dépots de garantie | AP12: =C12 -> Dépots de garantie | AQ12: =SUM(MAX(D12:E12),MAX(G12:H12),MAX(J12:K12),MAX(M12,N12),MAX(P12:Q12),MAX(S12:T12),MAX(V12:W12),MAX(Y12:Z12),MAX(AB12:AC12),MAX(AE12,AF12),MAX(AH12:AI12),MAX(AK12:AL12)) -> 0
C13: Apports personnels | AP13: =C13 -> Apports personnels | AQ13: =SUM(MAX(D13:E13),MAX(G13:H13),MAX(J13:K13),MAX(M13,N13),MAX(P13:Q13),MAX(S13:T13),MAX(V13:W13),MAX(Y13:Z13),MAX(AB13:AC13),MAX(AE13,AF13),MAX(AH13:AI13),MAX(AK13:AL13)) -> 0
C14: Financement | AP14: =C14 -> Financement | AQ14: =SUM(MAX(D14:E14),MAX(G14:H14),MAX(J14:K14),MAX(M14,N14),MAX(P14:Q14),MAX(S14:T14),MAX(V14:W14),MAX(Y14:Z14),MAX(AB14:AC14),MAX(AE14,AF14),MAX(AH14:AI14),MAX(AK14:AL14)) -> 0
C15: Subventions | AP15: =C15 -> Subventions | AQ15: =SUM(MAX(D15:E15),MAX(G15:H15),MAX(J15:K15),MAX(M15,N15),MAX(P15:Q15),MAX(S15:T15),MAX(V15:W15),MAX(Y15:Z15),MAX(AB15:AC15),MAX(AE15,AF15),MAX(AH15:AI15),MAX(AK15:AL15)) -> 0
C16: Autres | AP16: =C16 -> Autres | AQ16: =SUM(MAX(D16:E16),MAX(G16:H16),MAX(J16:K16),MAX(M16,N16),MAX(P16:Q16),MAX(S16:T16),MAX(V16:W16),MAX(Y16:Z16),MAX(AB16:AC16),MAX(AE16,AF16),MAX(AH16:AI16),MAX(AK16:AL16)) -> 0
C17: Total des Entrées | D17: =IF(SUM(D10:D16)=0,"",SUM(D10:D16)) | E17: =SUM(E10:E16) -> 0 | G17: =IF(SUM(G10:G16)=0,"",SUM(G10:G16)) | H17: =SUM(H10:H16) -> 0 | J17: =IF(SUM(J10:J16)=0,"",SUM(J10:J16)) | K17: =SUM(K10:K16) -> 0 | M17: =IF(SUM(M10:M16)=0,"",SUM(M10:M16)) | N17: =SUM(N10:N16) -> 0 | P17: =IF(SUM(P10:P16)=0,"",SUM(P10:P16)) | Q17: =SUM(Q10:Q16) -> 0 | S17: =IF(SUM(S10:S16)=0,"",SUM(S10:S16)) | T17: =SUM(T10:T16) -> 0 | V17: =IF(SUM(V10:V16)=0,"",SUM(V10:V16)) | W17: =SUM(W10:W16) -> 0 | Y17: =IF(SUM(Y10:Y16)=0,"",SUM(Y10:Y16)) | Z17: =SUM(Z10:Z16) -> 0 | AB17: =IF(SUM(AB10:AB16)=0,"",SUM(AB10:AB16)) | AC17: =SUM(AC10:AC16) -> 0 | AE17: =IF(SUM(AE10:AE16)=0,"",SUM(AE10:AE16)) | AF17: =SUM(AF10:AF16) -> 0 | AH17: =IF(SUM(AH10:AH16)=0,"",SUM(AH10:AH16)) | AI17: =SUM(AI10:AI16) -> 0 | AK17: =IF(SUM(AK10:AK16)=0,"",SUM(AK10:AK16)) | AL17: =SUM(AL10:AL16) -> 0 | AP17: Total des Entrées annuelles | AQ17: =SUM(AQ10:AS16) -> 0
C18: Différence | D18: =IF(D17="","",D17-E17) | G18: =IF(G17="","",G17-H17) | J18: =IF(J17="","",J17-K17) | M18: =IF(M17="","",M17-N17) | P18: =IF(P17="","",P17-Q17) | S18: =IF(S17="","",S17-T17) | V18: =IF(V17="","",V17-W17) | Y18: =IF(Y17="","",Y17-Z17) | AB18: =IF(AB17="","",AB17-AC17) | AE18: =IF(AE17="","",AE17-AF17) | AH18: =IF(AH17="","",AH17-AI17) | AK18: =IF(AK17="","",AK17-AL17)
C20: SORTIES | D20: =Menu!F22 -> 46174 | G20: =32+D20 -> 46206 | J20: =32+G20 -> 46238 | M20: =32+J20 -> 46270 | P20: =32+M20 -> 46302 | S20: =32+P20 -> 46334 | V20: =32+S20 -> 46366 | Y20: =32+V20 -> 46398 | AB20: =32+Y20 -> 46430 | AE20: =32+AB20 -> 46462 | AH20: =32+AE20 -> 46494 | AK20: =32+AH20 -> 46526 | AP20: SORTIES
D21: Suivi | E21: Budget | G21: Suivi | H21: Budget | J21: Suivi | K21: Budget | M21: Suivi | N21: Budget | P21: Suivi | Q21: Budget | S21: Suivi | T21: Budget | V21: Suivi | W21: Budget | Y21: Suivi | Z21: Budget | AB21: Suivi | AC21: Budget | AE21: Suivi | AF21: Budget | AH21: Suivi | AI21: Budget | AK21: Suivi | AL21: Budget
C22: Frais de gérance | AP22: =C22 -> Frais de gérance | AQ22: =SUM(MAX(D22:E22),MAX(G22:H22),MAX(J22:K22),MAX(M22,N22),MAX(P22:Q22),MAX(S22:T22),MAX(V22:W22),MAX(Y22:Z22),MAX(AB22:AC22),MAX(AE22,AF22),MAX(AH22:AI22),MAX(AK22:AL22)) -> 0
C23: Assurances | AP23: =C23 -> Assurances | AQ23: =SUM(MAX(D23:E23),MAX(G23:H23),MAX(J23:K23),MAX(M23,N23),MAX(P23:Q23),MAX(S23:T23),MAX(V23:W23),MAX(Y23:Z23),MAX(AB23:AC23),MAX(AE23,AF23),MAX(AH23:AI23),MAX(AK23:AL23)) -> 0
C24: Eau | AP24: =C24 -> Eau | AQ24: =SUM(MAX(D24:E24),MAX(G24:H24),MAX(J24:K24),MAX(M24,N24),MAX(P24:Q24),MAX(S24:T24),MAX(V24:W24),MAX(Y24:Z24),MAX(AB24:AC24),MAX(AE24,AF24),MAX(AH24:AI24),MAX(AK24:AL24)) -> 0
C25: Electricité/Gaz | AP25: =C25 -> Electricité/Gaz | AQ25: =SUM(MAX(D25:E25),MAX(G25:H25),MAX(J25:K25),MAX(M25,N25),MAX(P25:Q25),MAX(S25:T25),MAX(V25:W25),MAX(Y25:Z25),MAX(AB25:AC25),MAX(AE25,AF25),MAX(AH25:AI25),MAX(AK25:AL25)) -> 0
C26: Crédit immobilier principal | AP26: =C26 -> Crédit immobilier principal | AQ26: =SUM(MAX(D26:E26),MAX(G26:H26),MAX(J26:K26),MAX(M26,N26),MAX(P26:Q26),MAX(S26:T26),MAX(V26:W26),MAX(Y26:Z26),MAX(AB26:AC26),MAX(AE26,AF26),MAX(AH26:AI26),MAX(AK26:AL26)) -> 0
C27: Crédit secondaire | AP27: =C27 -> Crédit secondaire | AQ27: =SUM(MAX(D27:E27),MAX(G27:H27),MAX(J27:K27),MAX(M27,N27),MAX(P27:Q27),MAX(S27:T27),MAX(V27:W27),MAX(Y27:Z27),MAX(AB27:AC27),MAX(AE27,AF27),MAX(AH27:AI27),MAX(AK27:AL27)) -> 0
C28: Frais bancaires | AP28: =C28 -> Frais bancaires | AQ28: =SUM(MAX(D28:E28),MAX(G28:H28),MAX(J28:K28),MAX(M28,N28),MAX(P28:Q28),MAX(S28:T28),MAX(V28:W28),MAX(Y28:Z28),MAX(AB28:AC28),MAX(AE28,AF28),MAX(AH28:AI28),MAX(AK28:AL28)) -> 0
C29: Taxe foncière | AP29: =C29 -> Taxe foncière | AQ29: =SUM(MAX(D29:E29),MAX(G29:H29),MAX(J29:K29),MAX(M29,N29),MAX(P29:Q29),MAX(S29:T29),MAX(V29:W29),MAX(Y29:Z29),MAX(AB29:AC29),MAX(AE29,AF29),MAX(AH29:AI29),MAX(AK29:AL29)) -> 0
C30: Divers (travaux etc.) | AP30: =C30 -> Divers (travaux etc.) | AQ30: =SUM(MAX(D30:E30),MAX(G30:H30),MAX(J30:K30),MAX(M30,N30),MAX(P30:Q30),MAX(S30:T30),MAX(V30:W30),MAX(Y30:Z30),MAX(AB30:AC30),MAX(AE30,AF30),MAX(AH30:AI30),MAX(AK30:AL30)) -> 0
C31: Entretien / Nettoyage | AP31: =C31 -> Entretien / Nettoyage | AQ31: =SUM(MAX(D31:E31),MAX(G31:H31),MAX(J31:K31),MAX(M31,N31),MAX(P31:Q31),MAX(S31:T31),MAX(V31:W31),MAX(Y31:Z31),MAX(AB31:AC31),MAX(AE31,AF31),MAX(AH31:AI31),MAX(AK31:AL31)) -> 0
C32: Retraits ponctuels | AP32: =C32 -> Retraits ponctuels | AQ32: =SUM(MAX(D32:E32),MAX(G32:H32),MAX(J32:K32),MAX(M32,N32),MAX(P32:Q32),MAX(S32:T32),MAX(V32:W32),MAX(Y32:Z32),MAX(AB32:AC32),MAX(AE32,AF32),MAX(AH32:AI32),MAX(AK32:AL32)) -> 0
C33: Autres | AP33: =C33 -> Autres | AQ33: =SUM(MAX(D33:E33),MAX(G33:H33),MAX(J33:K33),MAX(M33,N33),MAX(P33:Q33),MAX(S33:T33),MAX(V33:W33),MAX(Y33:Z33),MAX(AB33:AC33),MAX(AE33,AF33),MAX(AH33:AI33),MAX(AK33:AL33)) -> 0
C34: Total des sorties | D34: =IF(SUM(D22:D33)=0,"",SUM(D22:D33)) | E34: =SUM(E22:E33) -> 0 | G34: =IF(SUM(G22:G33)=0,"",SUM(G22:G33)) | H34: =SUM(H22:H33) -> 0 | J34: =IF(SUM(J22:J33)=0,"",SUM(J22:J33)) | K34: =SUM(K22:K33) -> 0 | M34: =IF(SUM(M22:M33)=0,"",SUM(M22:M33)) | N34: =SUM(N22:N33) -> 0 | P34: =IF(SUM(P22:P33)=0,"",SUM(P22:P33)) | Q34: =SUM(Q22:Q33) -> 0 | S34: =IF(SUM(S22:S33)=0,"",SUM(S22:S33)) | T34: =SUM(T22:T33) -> 0 | V34: =IF(SUM(V22:V33)=0,"",SUM(V22:V33)) | W34: =SUM(W22:W33) -> 0 | Y34: =IF(SUM(Y22:Y33)=0,"",SUM(Y22:Y33)) | Z34: =SUM(Z22:Z33) -> 0 | AB34: =IF(SUM(AB22:AB33)=0,"",SUM(AB22:AB33)) | AC34: =SUM(AC22:AC33) -> 0 | AE34: =IF(SUM(AE22:AE33)=0,"",SUM(AE22:AE33)) | AF34: =SUM(AF22:AF33) -> 0 | AH34: =IF(SUM(AH22:AH33)=0,"",SUM(AH22:AH33)) | AI34: =SUM(AI22:AI33) -> 0 | AK34: =IF(SUM(AK22:AK33)=0,"",SUM(AK22:AK33)) | AL34: =SUM(AL22:AL33) -> 0 | AP34: Total des sorties annuelles | AQ34: =SUM(AQ22:AS33) -> 0
C35: Différence | D35: =IF(D34="","",E34-D34) | G35: =IF(G34="","",H34-G34) | J35: =IF(J34="","",K34-J34) | M35: =IF(M34="","",N34-M34) | P35: =IF(P34="","",Q34-P34) | S35: =IF(S34="","",T34-S34) | V35: =IF(V34="","",W34-V34) | Y35: =IF(Y34="","",Z34-Y34) | AB35: =IF(AB34="","",AC34-AB34) | AE35: =IF(AE34="","",AF34-AE34) | AH35: =IF(AH34="","",AI34-AH34) | AK35: =IF(AK34="","",AL34-AK34)
D37: =Menu!F22 -> 46174 | G37: =D37+32 -> 46206 | J37: =G37+32 -> 46238 | M37: =J37+32 -> 46270 | P37: =M37+32 -> 46302 | S37: =P37+32 -> 46334 | V37: =S37+32 -> 46366 | Y37: =V37+32 -> 46398 | AB37: =Y37+32 -> 46430 | AE37: =AB37+32 -> 46462 | AH37: =AE37+32 -> 46494 | AK37: =AH37+32 -> 46526
D38: Suivi | E38: Budget | G38: Suivi | H38: Budget | J38: Suivi | K38: Budget | M38: Suivi | N38: Budget | P38: Suivi | Q38: Budget | S38: Suivi | T38: Budget | V38: Suivi | W38: Budget | Y38: Suivi | Z38: Budget | AB38: Suivi | AC38: Budget | AE38: Suivi | AF38: Budget | AH38: Suivi | AI38: Budget | AK38: Suivi | AL38: Budget
